tasaklar
Error: Sub-process /usr/bin/dpkg returned an error code (1)
Setting up python3 (3.13.1-2) ...
running python rtupdate hooks for python3.13...
Traceback (most recent call last):
  File "/usr/bin/py3clean", line 209, in <module>
    main()
    ~~~~^^
  File "/usr/bin/py3clean", line 195, in main
    pfiles = set(dpf.from_package(options.package))
  File "/usr/share/python3/debpython/files.py", line 55, in from_package                                                        
    raise Exception("cannot get content of %s" % package_name)
Exception: cannot get content of command-not-found
error running python rtupdate hook command-not-found
Traceback (most recent call last):
  File "/usr/bin/py3clean", line 209, in <module>
    main()
    ~~~~^^
  File "/usr/bin/py3clean", line 195, in main
    pfiles = set(dpf.from_package(options.package))
  File "/usr/share/python3/debpython/files.py", line 55, in from_package                                                        
    raise Exception("cannot get content of %s" % package_name)
Exception: cannot get content of commix
error running python rtupdate hook commix
Traceback (most recent call last):
  File "/usr/bin/py3clean", line 209, in <module>
    main()
    ~~~~^^
  File "/usr/bin/py3clean", line 195, in main
    pfiles = set(dpf.from_package(options.package))
  File "/usr/share/python3/debpython/files.py", line 55, in from_package                                                        
    raise Exception("cannot get content of %s" % package_name)
Exception: cannot get content of creddump7
error running python rtupdate hook creddump7
Traceback (most recent call last):
  File "/usr/bin/py3clean", line 209, in <module>
    main()
    ~~~~^^
  File "/usr/bin/py3clean", line 195, in main
    pfiles = set(dpf.from_package(options.package))
  File "/usr/share/python3/debpython/files.py", line 55, in from_package                                                        
    raise Exception("cannot get content of %s" % package_name)
Exception: cannot get content of dnsrecon
error running python rtupdate hook dnsrecon
Traceback (most recent call last):
  File "/usr/bin/py3clean", line 209, in <module>
    main()
    ~~~~^^
  File "/usr/bin/py3clean", line 195, in main
    pfiles = set(dpf.from_package(options.package))
  File "/usr/share/python3/debpython/files.py", line 55, in from_package                                                        
    raise Exception("cannot get content of %s" % package_name)
Exception: cannot get content of fern-wifi-cracker
error running python rtupdate hook fern-wifi-cracker
Traceback (most recent call last):
  File "/usr/bin/py3clean", line 209, in <module>
    main()
    ~~~~^^
  File "/usr/bin/py3clean", line 195, in main
    pfiles = set(dpf.from_package(options.package))
  File "/usr/share/python3/debpython/files.py", line 55, in from_package                                                        
    raise Exception("cannot get content of %s" % package_name)
Exception: cannot get content of john-data
error running python rtupdate hook john-data
Traceback (most recent call last):
  File "/usr/bin/py3clean", line 209, in <module>
    main()
    ~~~~^^
  File "/usr/bin/py3clean", line 195, in main
    pfiles = set(dpf.from_package(options.package))
  File "/usr/share/python3/debpython/files.py", line 55, in from_package                                                        
    raise Exception("cannot get content of %s" % package_name)
Exception: cannot get content of kali-undercover
error running python rtupdate hook kali-undercover
Traceback (most recent call last):
  File "/usr/bin/py3clean", line 209, in <module>
    main()
    ~~~~^^
  File "/usr/bin/py3clean", line 195, in main
    pfiles = set(dpf.from_package(options.package))
  File "/usr/share/python3/debpython/files.py", line 55, in from_package                                                        
    raise Exception("cannot get content of %s" % package_name)
Exception: cannot get content of legion
error running python rtupdate hook legion
Traceback (most recent call last):
  File "/usr/bin/py3clean", line 209, in <module>
    main()
    ~~~~^^
  File "/usr/bin/py3clean", line 195, in main
    pfiles = set(dpf.from_package(options.package))
  File "/usr/share/python3/debpython/files.py", line 55, in from_package                                                        
    raise Exception("cannot get content of %s" % package_name)
Exception: cannot get content of powershell-empire
error running python rtupdate hook powershell-empire
Traceback (most recent call last):
  File "/usr/bin/py3clean", line 209, in <module>
    main()
    ~~~~^^
  File "/usr/bin/py3clean", line 195, in main
    pfiles = set(dpf.from_package(options.package))
  File "/usr/share/python3/debpython/files.py", line 55, in from_package                                                        
    raise Exception("cannot get content of %s" % package_name)
Exception: cannot get content of recon-ng
error running python rtupdate hook recon-ng
Traceback (most recent call last):
  File "/usr/bin/py3clean", line 209, in <module>
    main()
    ~~~~^^
  File "/usr/bin/py3clean", line 195, in main
    pfiles = set(dpf.from_package(options.package))
  File "/usr/share/python3/debpython/files.py", line 55, in from_package                                                        
    raise Exception("cannot get content of %s" % package_name)
Exception: cannot get content of responder
error running python rtupdate hook responder
Traceback (most recent call last):
  File "/usr/bin/py3clean", line 209, in <module>
    main()
    ~~~~^^
  File "/usr/bin/py3clean", line 195, in main
    pfiles = set(dpf.from_package(options.package))
  File "/usr/share/python3/debpython/files.py", line 55, in from_package                                                        
    raise Exception("cannot get content of %s" % package_name)
Exception: cannot get content of set
error running python rtupdate hook set
Traceback (most recent call last):
  File "/usr/bin/py3clean", line 209, in <module>
    main()
    ~~~~^^
  File "/usr/bin/py3clean", line 195, in main
    pfiles = set(dpf.from_package(options.package))
  File "/usr/share/python3/debpython/files.py", line 55, in from_package                                                        
    raise Exception("cannot get content of %s" % package_name)
Exception: cannot get content of spiderfoot
error running python rtupdate hook spiderfoot
Traceback (most recent call last):
  File "/usr/bin/py3clean", line 209, in <module>
    main()
    ~~~~^^
  File "/usr/bin/py3clean", line 195, in main
    pfiles = set(dpf.from_package(options.package))
  File "/usr/share/python3/debpython/files.py", line 55, in from_package                                                        
    raise Exception("cannot get content of %s" % package_name)
Exception: cannot get content of sqlmap
error running python rtupdate hook sqlmap
Traceback (most recent call last):
  File "/usr/bin/py3clean", line 209, in <module>
    main()
    ~~~~^^
  File "/usr/bin/py3clean", line 195, in main
    pfiles = set(dpf.from_package(options.package))
  File "/usr/share/python3/debpython/files.py", line 55, in from_package                                                        
    raise Exception("cannot get content of %s" % package_name)
Exception: cannot get content of system-config-printer-common
error running python rtupdate hook system-config-printer-common
Traceback (most recent call last):
  File "/usr/bin/py3clean", line 209, in <module>
    main()
    ~~~~^^
  File "/usr/bin/py3clean", line 195, in main
    pfiles = set(dpf.from_package(options.package))
  File "/usr/share/python3/debpython/files.py", line 55, in from_package                                                        
    raise Exception("cannot get content of %s" % package_name)
Exception: cannot get content of system-config-printer
error running python rtupdate hook system-config-printer
Traceback (most recent call last):
  File "/usr/bin/py3clean", line 209, in <module>
    main()
    ~~~~^^
  File "/usr/bin/py3clean", line 195, in main
    pfiles = set(dpf.from_package(options.package))
  File "/usr/share/python3/debpython/files.py", line 55, in from_package                                                        
    raise Exception("cannot get content of %s" % package_name)
Exception: cannot get content of unicorn-magic
error running python rtupdate hook unicorn-magic
dpkg: error processing package python3 (--configure):
 installed python3 package post-installation script subprocess returned error exit status 4
dpkg: dependency problems prevent configuration of python3-psutil:
 python3-psutil depends on python3 (>= 3~); however:
  Package python3 is not configured yet.
 python3-psutil depends on python3:any; however:
  Package python3 is not configured yet.

dpkg: error processing package python3-psutil (--configure):
 dependency problems - leaving unconfigured
dpkg: dependency problems prevent configuration of xfce4-panel-profiles:
 xfce4-panel-profiles depends on python3-psutil; however:
  Package python3-psutil is not configured yet.
 xfce4-panel-profiles depends on python3:any; however:
  Package python3 is not configured yet.

dpkg: error processing package xfce4-panel-profiles (--configure):
 dependency problems - leaving unconfigured
dpkg: dependency problems prevent configuration of mesa-vulkan-drivers:amd64:
 mesa-vulkan-drivers:amd64 depends on python3:any; however:
  Package python3 is not configured yet.

dpkg: error processing package mesa-vulkan-drivers:amd64 (--configure):
 dependency problems - leaving unconfigured
Errors were encountered while processing:
 python3
 python3-psutil
 xfce4-panel-profiles
 mesa-vulkan-drivers:amd64







